2013-08-05 00:26:43,896 - blog_logger - ERROR - <urlopen error [Errno 111] Connection refused>
Traceback (most recent call last):
  File "blog_through_baidu.py", line 11, in <module>
    obj.main()
  File "/home/lgy/Code/lgy_git/Python/newspider/baidu.py", line 158, in main
    count=self.searchWrapper(count)
  File "/home/lgy/Code/lgy_git/Python/newspider/baidu.py", line 124, in searchWrapper
    self.search4EachItem(items,keyword)
  File "/home/lgy/Code/lgy_git/Python/newspider/baidu.py", line 132, in search4EachItem
    self.itemProcess(item,keyword)
  File "/home/lgy/Code/lgy_git/Python/newspider/baidu.py", line 74, in itemProcess
    self.INFO_SOURCE_ID,self.keywordId, createdAt, 0,0)
  File "/home/lgy/Code/lgy_git/Python/newspider/blog_utils.py", line 38, in store_blog_post
    store_category('blog', str(sql_post.id))
  File "/home/lgy/Code/lgy_git/Python/newspider/utils.py", line 34, in store_category
    response = urllib2.urlopen(url)
  File "/usr/lib/python2.7/urllib2.py", line 126, in urlopen
    return _opener.open(url, data, timeout)
  File "/usr/lib/python2.7/urllib2.py", line 400, in open
    response = self._open(req, data)
  File "/usr/lib/python2.7/urllib2.py", line 418, in _open
    '_open', req)
  File "/usr/lib/python2.7/urllib2.py", line 378, in _call_chain
    result = func(*args)
  File "/usr/lib/python2.7/urllib2.py", line 1207, in http_open
    return self.do_open(httplib.HTTPConnection, req)
  File "/usr/lib/python2.7/urllib2.py", line 1177, in do_open
    raise URLError(err)
URLError: <urlopen error [Errno 111] Connection refused>
2013-08-05 00:26:47,208 - blog_logger - ERROR - year=444 is before 1900; the datetime strftime() methods require year >= 1900
Traceback (most recent call last):
  File "blog_through_baidu.py", line 18, in <module>
    obj.main()
  File "/home/lgy/Code/lgy_git/Python/newspider/baidu.py", line 158, in main
    count=self.searchWrapper(count)
  File "/home/lgy/Code/lgy_git/Python/newspider/baidu.py", line 124, in searchWrapper
    self.search4EachItem(items,keyword)
  File "/home/lgy/Code/lgy_git/Python/newspider/baidu.py", line 132, in search4EachItem
    self.itemProcess(item,keyword)
  File "/home/lgy/Code/lgy_git/Python/newspider/baidu.py", line 66, in itemProcess
    createdAt = self.convertTime(citeTime)
  File "/home/lgy/Code/lgy_git/Python/newspider/baidu.py", line 113, in convertTime
    return time.strftime("%Y-%m-%d")
ValueError: year=444 is before 1900; the datetime strftime() methods require year >= 1900
2013-08-05 00:26:59,198 - blog_logger - ERROR - <urlopen error [Errno 111] Connection refused>
Traceback (most recent call last):
  File "blog_through_baidu.py", line 25, in <module>
    obj.main()
  File "/home/lgy/Code/lgy_git/Python/newspider/baidu.py", line 158, in main
    count=self.searchWrapper(count)
  File "/home/lgy/Code/lgy_git/Python/newspider/baidu.py", line 124, in searchWrapper
    self.search4EachItem(items,keyword)
  File "/home/lgy/Code/lgy_git/Python/newspider/baidu.py", line 132, in search4EachItem
    self.itemProcess(item,keyword)
  File "/home/lgy/Code/lgy_git/Python/newspider/baidu.py", line 74, in itemProcess
    self.INFO_SOURCE_ID,self.keywordId, createdAt, 0,0)
  File "/home/lgy/Code/lgy_git/Python/newspider/blog_utils.py", line 38, in store_blog_post
    store_category('blog', str(sql_post.id))
  File "/home/lgy/Code/lgy_git/Python/newspider/utils.py", line 34, in store_category
    response = urllib2.urlopen(url)
  File "/usr/lib/python2.7/urllib2.py", line 126, in urlopen
    return _opener.open(url, data, timeout)
  File "/usr/lib/python2.7/urllib2.py", line 400, in open
    response = self._open(req, data)
  File "/usr/lib/python2.7/urllib2.py", line 418, in _open
    '_open', req)
  File "/usr/lib/python2.7/urllib2.py", line 378, in _call_chain
    result = func(*args)
  File "/usr/lib/python2.7/urllib2.py", line 1207, in http_open
    return self.do_open(httplib.HTTPConnection, req)
  File "/usr/lib/python2.7/urllib2.py", line 1177, in do_open
    raise URLError(err)
URLError: <urlopen error [Errno 111] Connection refused>
2013-08-05 00:27:19,241 - blog_logger - ERROR - <urlopen error [Errno 111] Connection refused>
Traceback (most recent call last):
  File "blog_through_baidu.py", line 32, in <module>
    obj.main()
  File "/home/lgy/Code/lgy_git/Python/newspider/baidu.py", line 158, in main
    count=self.searchWrapper(count)
  File "/home/lgy/Code/lgy_git/Python/newspider/baidu.py", line 124, in searchWrapper
    self.search4EachItem(items,keyword)
  File "/home/lgy/Code/lgy_git/Python/newspider/baidu.py", line 132, in search4EachItem
    self.itemProcess(item,keyword)
  File "/home/lgy/Code/lgy_git/Python/newspider/baidu.py", line 74, in itemProcess
    self.INFO_SOURCE_ID,self.keywordId, createdAt, 0,0)
  File "/home/lgy/Code/lgy_git/Python/newspider/blog_utils.py", line 38, in store_blog_post
    store_category('blog', str(sql_post.id))
  File "/home/lgy/Code/lgy_git/Python/newspider/utils.py", line 34, in store_category
    response = urllib2.urlopen(url)
  File "/usr/lib/python2.7/urllib2.py", line 126, in urlopen
    return _opener.open(url, data, timeout)
  File "/usr/lib/python2.7/urllib2.py", line 400, in open
    response = self._open(req, data)
  File "/usr/lib/python2.7/urllib2.py", line 418, in _open
    '_open', req)
  File "/usr/lib/python2.7/urllib2.py", line 378, in _call_chain
    result = func(*args)
  File "/usr/lib/python2.7/urllib2.py", line 1207, in http_open
    return self.do_open(httplib.HTTPConnection, req)
  File "/usr/lib/python2.7/urllib2.py", line 1177, in do_open
    raise URLError(err)
URLError: <urlopen error [Errno 111] Connection refused>
