2013-08-04 21:58:46,921 - news_logger - ERROR - 'NoneType' object has no attribute 'find'
Traceback (most recent call last):
  File "news_through_google.py", line 56, in <module>
    obj.main()
  File "/home/lgy/Code/lgy_git/Python/newspider/BaseBBS.py", line 46, in main
    count=self.searchWrapper(count)
  File "/home/lgy/Code/lgy_git/Python/newspider/google_search.py", line 128, in searchWrapper
    self.search4EachItem(items,keyword)
  File "/home/lgy/Code/lgy_git/Python/newspider/google_search.py", line 136, in search4EachItem
    self.itemProcess(item,keyword)
  File "/home/lgy/Code/lgy_git/Python/newspider/google_search.py", line 98, in itemProcess
    content = item.find('div',{'class':'s'}).find('span',{'class':'st'}).text
AttributeError: 'NoneType' object has no attribute 'find'
2013-08-04 22:06:39,426 - news_logger - ERROR - 'NoneType' object has no attribute 'find'
Traceback (most recent call last):
  File "news_through_google.py", line 91, in <module>
    obj.main()
  File "/home/lgy/Code/lgy_git/Python/newspider/BaseBBS.py", line 46, in main
    count=self.searchWrapper(count)
  File "/home/lgy/Code/lgy_git/Python/newspider/google_search.py", line 128, in searchWrapper
    self.search4EachItem(items,keyword)
  File "/home/lgy/Code/lgy_git/Python/newspider/google_search.py", line 136, in search4EachItem
    self.itemProcess(item,keyword)
  File "/home/lgy/Code/lgy_git/Python/newspider/google_search.py", line 98, in itemProcess
    content = item.find('div',{'class':'s'}).find('span',{'class':'st'}).text
AttributeError: 'NoneType' object has no attribute 'find'
2013-08-04 22:07:00,821 - news_logger - ERROR - 'NoneType' object has no attribute 'find'
Traceback (most recent call last):
  File "news_through_google.py", line 98, in <module>
    obj.main()
  File "/home/lgy/Code/lgy_git/Python/newspider/BaseBBS.py", line 46, in main
    count=self.searchWrapper(count)
  File "/home/lgy/Code/lgy_git/Python/newspider/google_search.py", line 128, in searchWrapper
    self.search4EachItem(items,keyword)
  File "/home/lgy/Code/lgy_git/Python/newspider/google_search.py", line 136, in search4EachItem
    self.itemProcess(item,keyword)
  File "/home/lgy/Code/lgy_git/Python/newspider/google_search.py", line 98, in itemProcess
    content = item.find('div',{'class':'s'}).find('span',{'class':'st'}).text
AttributeError: 'NoneType' object has no attribute 'find'
2013-08-04 22:11:29,280 - news_logger - ERROR - HTTP Error 503: Service Unavailable
Traceback (most recent call last):
  File "news_through_google.py", line 112, in <module>
    obj.main()
  File "/home/lgy/Code/lgy_git/Python/newspider/BaseBBS.py", line 46, in main
    count=self.searchWrapper(count)
  File "/home/lgy/Code/lgy_git/Python/newspider/google_search.py", line 126, in searchWrapper
    items = self.nextPage(keyword)
  File "/home/lgy/Code/lgy_git/Python/newspider/google_search.py", line 77, in nextPage
    response = opener.open(req)
  File "/usr/lib/python2.7/urllib2.py", line 406, in open
    response = meth(req, response)
  File "/usr/lib/python2.7/urllib2.py", line 519, in http_response
    'http', request, response, code, msg, hdrs)
  File "/usr/lib/python2.7/urllib2.py", line 438, in error
    result = self._call_chain(*args)
  File "/usr/lib/python2.7/urllib2.py", line 378, in _call_chain
    result = func(*args)
  File "/usr/lib/python2.7/urllib2.py", line 625, in http_error_302
    return self.parent.open(new, timeout=req.timeout)
  File "/usr/lib/python2.7/urllib2.py", line 406, in open
    response = meth(req, response)
  File "/usr/lib/python2.7/urllib2.py", line 519, in http_response
    'http', request, response, code, msg, hdrs)
  File "/usr/lib/python2.7/urllib2.py", line 444, in error
    return self._call_chain(*args)
  File "/usr/lib/python2.7/urllib2.py", line 378, in _call_chain
    result = func(*args)
  File "/usr/lib/python2.7/urllib2.py", line 527, in http_error_default
    raise HTTPError(req.get_full_url(), code, msg, hdrs, fp)
HTTPError: HTTP Error 503: Service Unavailable
2013-08-04 22:12:31,504 - news_logger - ERROR - HTTP Error 503: Service Unavailable
Traceback (most recent call last):
  File "news_through_google.py", line 119, in <module>
    obj.main()
  File "/home/lgy/Code/lgy_git/Python/newspider/BaseBBS.py", line 46, in main
    count=self.searchWrapper(count)
  File "/home/lgy/Code/lgy_git/Python/newspider/google_search.py", line 126, in searchWrapper
    items = self.nextPage(keyword)
  File "/home/lgy/Code/lgy_git/Python/newspider/google_search.py", line 77, in nextPage
    response = opener.open(req)
  File "/usr/lib/python2.7/urllib2.py", line 406, in open
    response = meth(req, response)
  File "/usr/lib/python2.7/urllib2.py", line 519, in http_response
    'http', request, response, code, msg, hdrs)
  File "/usr/lib/python2.7/urllib2.py", line 438, in error
    result = self._call_chain(*args)
  File "/usr/lib/python2.7/urllib2.py", line 378, in _call_chain
    result = func(*args)
  File "/usr/lib/python2.7/urllib2.py", line 625, in http_error_302
    return self.parent.open(new, timeout=req.timeout)
  File "/usr/lib/python2.7/urllib2.py", line 406, in open
    response = meth(req, response)
  File "/usr/lib/python2.7/urllib2.py", line 519, in http_response
    'http', request, response, code, msg, hdrs)
  File "/usr/lib/python2.7/urllib2.py", line 444, in error
    return self._call_chain(*args)
  File "/usr/lib/python2.7/urllib2.py", line 378, in _call_chain
    result = func(*args)
  File "/usr/lib/python2.7/urllib2.py", line 527, in http_error_default
    raise HTTPError(req.get_full_url(), code, msg, hdrs, fp)
HTTPError: HTTP Error 503: Service Unavailable
2013-08-04 22:13:34,884 - news_logger - ERROR - HTTP Error 503: Service Unavailable
Traceback (most recent call last):
  File "news_through_google.py", line 126, in <module>
    obj.main()
  File "/home/lgy/Code/lgy_git/Python/newspider/BaseBBS.py", line 46, in main
    count=self.searchWrapper(count)
  File "/home/lgy/Code/lgy_git/Python/newspider/google_search.py", line 126, in searchWrapper
    items = self.nextPage(keyword)
  File "/home/lgy/Code/lgy_git/Python/newspider/google_search.py", line 77, in nextPage
    response = opener.open(req)
  File "/usr/lib/python2.7/urllib2.py", line 406, in open
    response = meth(req, response)
  File "/usr/lib/python2.7/urllib2.py", line 519, in http_response
    'http', request, response, code, msg, hdrs)
  File "/usr/lib/python2.7/urllib2.py", line 438, in error
    result = self._call_chain(*args)
  File "/usr/lib/python2.7/urllib2.py", line 378, in _call_chain
    result = func(*args)
  File "/usr/lib/python2.7/urllib2.py", line 625, in http_error_302
    return self.parent.open(new, timeout=req.timeout)
  File "/usr/lib/python2.7/urllib2.py", line 406, in open
    response = meth(req, response)
  File "/usr/lib/python2.7/urllib2.py", line 519, in http_response
    'http', request, response, code, msg, hdrs)
  File "/usr/lib/python2.7/urllib2.py", line 444, in error
    return self._call_chain(*args)
  File "/usr/lib/python2.7/urllib2.py", line 378, in _call_chain
    result = func(*args)
  File "/usr/lib/python2.7/urllib2.py", line 527, in http_error_default
    raise HTTPError(req.get_full_url(), code, msg, hdrs, fp)
HTTPError: HTTP Error 503: Service Unavailable
2013-08-04 22:14:39,171 - news_logger - ERROR - HTTP Error 503: Service Unavailable
Traceback (most recent call last):
  File "news_through_google.py", line 133, in <module>
    obj.main()
  File "/home/lgy/Code/lgy_git/Python/newspider/BaseBBS.py", line 46, in main
    count=self.searchWrapper(count)
  File "/home/lgy/Code/lgy_git/Python/newspider/google_search.py", line 126, in searchWrapper
    items = self.nextPage(keyword)
  File "/home/lgy/Code/lgy_git/Python/newspider/google_search.py", line 77, in nextPage
    response = opener.open(req)
  File "/usr/lib/python2.7/urllib2.py", line 406, in open
    response = meth(req, response)
  File "/usr/lib/python2.7/urllib2.py", line 519, in http_response
    'http', request, response, code, msg, hdrs)
  File "/usr/lib/python2.7/urllib2.py", line 438, in error
    result = self._call_chain(*args)
  File "/usr/lib/python2.7/urllib2.py", line 378, in _call_chain
    result = func(*args)
  File "/usr/lib/python2.7/urllib2.py", line 625, in http_error_302
    return self.parent.open(new, timeout=req.timeout)
  File "/usr/lib/python2.7/urllib2.py", line 406, in open
    response = meth(req, response)
  File "/usr/lib/python2.7/urllib2.py", line 519, in http_response
    'http', request, response, code, msg, hdrs)
  File "/usr/lib/python2.7/urllib2.py", line 444, in error
    return self._call_chain(*args)
  File "/usr/lib/python2.7/urllib2.py", line 378, in _call_chain
    result = func(*args)
  File "/usr/lib/python2.7/urllib2.py", line 527, in http_error_default
    raise HTTPError(req.get_full_url(), code, msg, hdrs, fp)
HTTPError: HTTP Error 503: Service Unavailable
2013-08-05 00:12:31,300 - news_logger - ERROR - 'NoneType' object has no attribute 'find'
Traceback (most recent call last):
  File "news_through_google.py", line 33, in <module>
    obj.main()
  File "/home/lgy/Code/lgy_git/Python/newspider/BaseBBS.py", line 46, in main
    count=self.searchWrapper(count)
  File "/home/lgy/Code/lgy_git/Python/newspider/google_search.py", line 128, in searchWrapper
    self.search4EachItem(items,keyword)
  File "/home/lgy/Code/lgy_git/Python/newspider/google_search.py", line 136, in search4EachItem
    self.itemProcess(item,keyword)
  File "/home/lgy/Code/lgy_git/Python/newspider/google_search.py", line 98, in itemProcess
    content = item.find('div',{'class':'s'}).find('span',{'class':'st'}).text
AttributeError: 'NoneType' object has no attribute 'find'
2013-08-05 00:27:33,058 - news_logger - ERROR - 'NoneType' object has no attribute 'find'
Traceback (most recent call last):
  File "news_through_google.py", line 61, in <module>
    obj.main()
  File "/home/lgy/Code/lgy_git/Python/newspider/BaseBBS.py", line 46, in main
    count=self.searchWrapper(count)
  File "/home/lgy/Code/lgy_git/Python/newspider/google_search.py", line 128, in searchWrapper
    count += len(items)
  File "/home/lgy/Code/lgy_git/Python/newspider/google_search.py", line 136, in search4EachItem
    for item in items:
  File "/home/lgy/Code/lgy_git/Python/newspider/google_search.py", line 98, in itemProcess
    return
AttributeError: 'NoneType' object has no attribute 'find'
2013-08-05 00:34:40,172 - news_logger - ERROR - timed out
Traceback (most recent call last):
  File "news_through_baidu.py", line 55, in <module>
    obj.main()
  File "/home/lgy/Code/lgy_git/Python/newspider/baidu.py", line 157, in main
    
  File "/home/lgy/Code/lgy_git/Python/newspider/baidu.py", line 121, in searchWrapper
    while not isFinished:
  File "/home/lgy/Code/lgy_git/Python/newspider/baidu.py", line 34, in nextPage
    content = urllib2.urlopen(url).read()
  File "/usr/lib/python2.7/socket.py", line 351, in read
    data = self._sock.recv(rbufsize)
  File "/usr/lib/python2.7/httplib.py", line 561, in read
    s = self.fp.read(amt)
  File "/usr/lib/python2.7/socket.py", line 380, in read
    data = self._sock.recv(left)
timeout: timed out
2013-08-05 00:36:12,287 - news_logger - ERROR - <urlopen error [Errno 111] Connection refused>
Traceback (most recent call last):
  File "/home/lgy/Code/lgy_git/Python/newspider/news_sczx.py", line 56, in main
    obj.main()
  File "/home/lgy/Code/lgy_git/Python/newspider/BaseNews.py", line 46, in main
    count=self.searchWrapper(count)
  File "/home/lgy/Code/lgy_git/Python/newspider/BaseNews.py", line 66, in searchWrapper
    self.search4EachItem(items)
  File "/home/lgy/Code/lgy_git/Python/newspider/BaseNews.py", line 98, in search4EachItem
    self.itemProcess(item)
  File "/home/lgy/Code/lgy_git/Python/newspider/news_sczx.py", line 46, in itemProcess
    self.INFO_SOURCE_ID, createdAt, self.keywordId)
  File "/home/lgy/Code/lgy_git/Python/newspider/news_utils.py", line 56, in add_news_to_session
    store_category('news', str(sql_news.id))
  File "/home/lgy/Code/lgy_git/Python/newspider/utils.py", line 34, in store_category
    response = urllib2.urlopen(url)
  File "/usr/lib/python2.7/urllib2.py", line 126, in urlopen
    return _opener.open(url, data, timeout)
  File "/usr/lib/python2.7/urllib2.py", line 400, in open
    response = self._open(req, data)
  File "/usr/lib/python2.7/urllib2.py", line 418, in _open
    '_open', req)
  File "/usr/lib/python2.7/urllib2.py", line 378, in _call_chain
    result = func(*args)
  File "/usr/lib/python2.7/urllib2.py", line 1207, in http_open
    return self.do_open(httplib.HTTPConnection, req)
  File "/usr/lib/python2.7/urllib2.py", line 1177, in do_open
    raise URLError(err)
URLError: <urlopen error [Errno 111] Connection refused>
2013-09-03 11:12:55,438 - news_logger - ERROR - <urlopen error [Errno 111] Connection refused>
Traceback (most recent call last):
  File "news_scxww.py", line 65, in main
    obj.main()
  File "/home/lgy/Code/lgy_git/Python/newspider/BaseNews.py", line 46, in main
    count=self.searchWrapper(count)
  File "/home/lgy/Code/lgy_git/Python/newspider/BaseNews.py", line 66, in searchWrapper
    self.search4EachItem(items)
  File "/home/lgy/Code/lgy_git/Python/newspider/BaseNews.py", line 98, in search4EachItem
    self.itemProcess(item)
  File "news_scxww.py", line 44, in itemProcess
    self.INFO_SOURCE_ID, createdAt, self.keywordId)
  File "/home/lgy/Code/lgy_git/Python/newspider/news_utils.py", line 56, in add_news_to_session
    store_category('news', str(sql_news.id))
  File "/home/lgy/Code/lgy_git/Python/newspider/utils.py", line 34, in store_category
    response = urllib2.urlopen(url)
  File "/usr/lib/python2.7/urllib2.py", line 126, in urlopen
    return _opener.open(url, data, timeout)
  File "/usr/lib/python2.7/urllib2.py", line 400, in open
    response = self._open(req, data)
  File "/usr/lib/python2.7/urllib2.py", line 418, in _open
    '_open', req)
  File "/usr/lib/python2.7/urllib2.py", line 378, in _call_chain
    result = func(*args)
  File "/usr/lib/python2.7/urllib2.py", line 1207, in http_open
    return self.do_open(httplib.HTTPConnection, req)
  File "/usr/lib/python2.7/urllib2.py", line 1177, in do_open
    raise URLError(err)
URLError: <urlopen error [Errno 111] Connection refused>
2013-09-03 11:13:44,340 - news_logger - ERROR - <urlopen error [Errno 111] Connection refused>
Traceback (most recent call last):
  File "news_sczx.py", line 56, in main
    obj.main()
  File "/home/lgy/Code/lgy_git/Python/newspider/BaseNews.py", line 46, in main
    count=self.searchWrapper(count)
  File "/home/lgy/Code/lgy_git/Python/newspider/BaseNews.py", line 66, in searchWrapper
    self.search4EachItem(items)
  File "/home/lgy/Code/lgy_git/Python/newspider/BaseNews.py", line 98, in search4EachItem
    self.itemProcess(item)
  File "news_sczx.py", line 46, in itemProcess
    self.INFO_SOURCE_ID, createdAt, self.keywordId)
  File "/home/lgy/Code/lgy_git/Python/newspider/news_utils.py", line 56, in add_news_to_session
    store_category('news', str(sql_news.id))
  File "/home/lgy/Code/lgy_git/Python/newspider/utils.py", line 34, in store_category
    response = urllib2.urlopen(url)
  File "/usr/lib/python2.7/urllib2.py", line 126, in urlopen
    return _opener.open(url, data, timeout)
  File "/usr/lib/python2.7/urllib2.py", line 400, in open
    response = self._open(req, data)
  File "/usr/lib/python2.7/urllib2.py", line 418, in _open
    '_open', req)
  File "/usr/lib/python2.7/urllib2.py", line 378, in _call_chain
    result = func(*args)
  File "/usr/lib/python2.7/urllib2.py", line 1207, in http_open
    return self.do_open(httplib.HTTPConnection, req)
  File "/usr/lib/python2.7/urllib2.py", line 1177, in do_open
    raise URLError(err)
URLError: <urlopen error [Errno 111] Connection refused>
2013-09-03 11:14:36,013 - news_logger - ERROR - HTTP Error 400: Bad Request
Traceback (most recent call last):
  File "news_sc_china.py", line 81, in main
    obj.main()
  File "/home/lgy/Code/lgy_git/Python/newspider/BaseNews.py", line 46, in main
    count=self.searchWrapper(count)
  File "/home/lgy/Code/lgy_git/Python/newspider/BaseNews.py", line 64, in searchWrapper
    items = self.nextPage(keyword)
  File "news_sc_china.py", line 17, in nextPage
    content = urllib2.urlopen(url).read()
  File "/usr/lib/python2.7/urllib2.py", line 126, in urlopen
    return _opener.open(url, data, timeout)
  File "/usr/lib/python2.7/urllib2.py", line 406, in open
    response = meth(req, response)
  File "/usr/lib/python2.7/urllib2.py", line 519, in http_response
    'http', request, response, code, msg, hdrs)
  File "/usr/lib/python2.7/urllib2.py", line 444, in error
    return self._call_chain(*args)
  File "/usr/lib/python2.7/urllib2.py", line 378, in _call_chain
    result = func(*args)
  File "/usr/lib/python2.7/urllib2.py", line 527, in http_error_default
    raise HTTPError(req.get_full_url(), code, msg, hdrs, fp)
HTTPError: HTTP Error 400: Bad Request
