2013-08-26 16:01:36,798 - weibo_logger - ERROR - <urlopen error [Errno 111] Connection refused>
Traceback (most recent call last):
  File "sina_weibo_crawl.py", line 512, in main
    search_for_new_statuses()
  File "sina_weibo_crawl.py", line 167, in search_for_new_statuses
    add_status_and_user_to_session(status, keyword.id)
  File "sina_weibo_crawl.py", line 381, in add_status_and_user_to_session
    store_category('weibo', str(sql_status.id))
  File "/home/lgy/Code/lgy_git/Python/utils.py", line 32, in store_category
    response = urllib2.urlopen(url)
  File "/usr/lib/python2.7/urllib2.py", line 126, in urlopen
    return _opener.open(url, data, timeout)
  File "/usr/lib/python2.7/urllib2.py", line 400, in open
    response = self._open(req, data)
  File "/usr/lib/python2.7/urllib2.py", line 418, in _open
    '_open', req)
  File "/usr/lib/python2.7/urllib2.py", line 378, in _call_chain
    result = func(*args)
  File "/usr/lib/python2.7/urllib2.py", line 1207, in http_open
    return self.do_open(httplib.HTTPConnection, req)
  File "/usr/lib/python2.7/urllib2.py", line 1177, in do_open
    raise URLError(err)
URLError: <urlopen error [Errno 111] Connection refused>
