2014-03-11 18:27:20,396 - weibo_logger - ERROR - <urlopen error [Errno 111] Connection refused>
Traceback (most recent call last):
  File "weibo_crawl_sina.py", line 511, in main
    search_for_new_statuses()
  File "weibo_crawl_sina.py", line 160, in search_for_new_statuses
    search_statuses = client.search.statuses.get(q=keyword.str, count=50, starttime=starttime)
  File "/home/lgy/lgy_git/Spider/Python/sina_api.py", line 248, in __call__
    return _http_call('%s%s.json' % (self._client.api_url, self._path), method, self._client.access_token, **kw)
  File "/home/lgy/lgy_git/Spider/Python/sina_api.py", line 147, in _http_call
    resp = urllib2.urlopen(req)
  File "/usr/lib/python2.6/urllib2.py", line 126, in urlopen
    return _opener.open(url, data, timeout)
  File "/usr/lib/python2.6/urllib2.py", line 391, in open
    response = self._open(req, data)
  File "/usr/lib/python2.6/urllib2.py", line 409, in _open
    '_open', req)
  File "/usr/lib/python2.6/urllib2.py", line 369, in _call_chain
    result = func(*args)
  File "/usr/lib/python2.6/urllib2.py", line 1180, in https_open
    return self.do_open(httplib.HTTPSConnection, req)
  File "/usr/lib/python2.6/urllib2.py", line 1147, in do_open
    raise URLError(err)
URLError: <urlopen error [Errno 111] Connection refused>
